Workbook

Sheet Quiz
A1: Appinium Quiz Creation Template v1
A3: Quiz Title | B3: Black Belt | E3: Duration (mins) | G3: =IF(ISBLANK($K$9),RIGHT(B14,2)*2,$K$9*2) -> 6 | I3: Background Image URL | K3: https://myciscosalesconnect.file.force.com/sfc/dist/version/download/?oid=00D8c000005u363&ids=0688c00000Dc6wG&d=%2Fa%2F8c000000gIsr%2FCk08eVzNYlxF3RMjfyfL6irDN2NBswxFxyH_0jWHUgU&asPdf=false | L3: Anshul
A5: Description | E5: Language | G5: English | I5: Content Trace ID
A7: Additional Information | E7: Passing Score | G7: 0.8 | I7: Content Source
A9: Quiz Page Name | B9: Page 01 | E9: Authors | G9: anshulsi, tepatil | I9: Question Display Count
A11: Description | I11: LMS Sharing Rules | K11: All Partners
A14: Question Count:- | B14: =COUNTA(A16:$A$200) -> 3
A15: Question Type | B15: Question Text | C15: Option1 | D15: Correct Answer1 | E15: Option2 | F15: Correct Answer2 | G15: Option3 | H15: Correct Answer3 | I15: Option4 | J15: Correct Answer4 | K15: Option5 | L15: Correct Answer5
A16: Multiple Choice | B16: Do not populate this template. Download a copy and use it. | C16: O1 | D16: No | E16: O2 | F16: Yes | G16: O3 | H16: Yes | I16: o4 | J16: No | K16: O5 | L16: No
A17: Single Choice | B17: SQ2 | C17: O1 | D17: Yes | E17: O2 | F17: No | G17: O3 | H17: No | I17: O4 | J17: No | K17: O5 | L17: No
A18: True/False | B18: SQ3 | C18: TRUE | D18: Yes | E18: FALSE | F18: No
XEP1048570: Created by: Anshul Singh

Sheet Assessment
A1: Topic | B1: Question Type | C1: Question Text | D1: Answer Choice 1 | E1: Answer Choice 2 | F1: Answer Choice 3 | G1: Answer Choice 4 | H1: Answer Choice 5 | I1: Answer Choice 6 | J1: Score
A2: Mandatory Field | B2: =IF(ISBLANK($C2),"","MCQ") -> MCQ | C2: Questiion text 1000 chracters max | D2: Answer 1 (max 400 characters) | E2: *Answer 2 (least 2 options) | F2: Answer 3 (least 1 correct answer) | G2: Answer 4 | H2: Answer 5 | I2: Answer 6 (max 6 options) | J2: {=IF(ISBLANK($C2),"",SUMPRODUCT(--(LEFT(D2:I2, 1) = "*"))*50)} -> 50
B3: =IF(ISBLANK($C3),"","MCQ") | J3: {=IF(ISBLANK($C3),"",SUMPRODUCT(--(LEFT(D3:I3, 1) = "*"))*50)}
B4: =IF(ISBLANK($C4),"","MCQ") | J4: {=IF(ISBLANK($C4),"",SUMPRODUCT(--(LEFT(D4:I4, 1) = "*"))*50)}
B5: =IF(ISBLANK($C5),"","MCQ") | J5: {=IF(ISBLANK($C5),"",SUMPRODUCT(--(LEFT(D5:I5, 1) = "*"))*50)}
B6: =IF(ISBLANK($C6),"","MCQ") | J6: {=IF(ISBLANK($C6),"",SUMPRODUCT(--(LEFT(D6:I6, 1) = "*"))*50)}
B7: =IF(ISBLANK($C7),"","MCQ") | J7: {=IF(ISBLANK($C7),"",SUMPRODUCT(--(LEFT(D7:I7, 1) = "*"))*50)}
B8: =IF(ISBLANK($C8),"","MCQ") | J8: {=IF(ISBLANK($C8),"",SUMPRODUCT(--(LEFT(D8:I8, 1) = "*"))*50)}
B9: =IF(ISBLANK($C9),"","MCQ") | J9: {=IF(ISBLANK($C9),"",SUMPRODUCT(--(LEFT(D9:I9, 1) = "*"))*50)}
B10: =IF(ISBLANK($C10),"","MCQ") | J10: {=IF(ISBLANK($C10),"",SUMPRODUCT(--(LEFT(D10:I10, 1) = "*"))*50)}
B11: =IF(ISBLANK($C11),"","MCQ") | J11: {=IF(ISBLANK($C11),"",SUMPRODUCT(--(LEFT(D11:I11, 1) = "*"))*50)}
B12: =IF(ISBLANK($C12),"","MCQ") | J12: {=IF(ISBLANK($C12),"",SUMPRODUCT(--(LEFT(D12:I12, 1) = "*"))*50)}
B13: =IF(ISBLANK($C13),"","MCQ") | J13: {=IF(ISBLANK($C13),"",SUMPRODUCT(--(LEFT(D13:I13, 1) = "*"))*50)}
B14: =IF(ISBLANK($C14),"","MCQ") | J14: {=IF(ISBLANK($C14),"",SUMPRODUCT(--(LEFT(D14:I14, 1) = "*"))*50)}
... B1000: =IF(ISBLANK($C1000),"","MCQ") | J1000: {=IF(ISBLANK($C1000),"",SUMPRODUCT(--(LEFT(D1000:I1000, 1) = "*"))*50)}

Sheet Assess.Details
A1: Mindtickle Quiz Creation Template v1
B3: Quiz Title | C3: Character Limit 100. Must be unique.
B5: Description | C5: Character Limit 1000
B7: Passing Score | C7: 0.8
B9: Question Diplay Count | C9: 0.8
B11: Total Questions | C11: =COUNTA(Assessment!$C:$C)-1 -> 1

Sheet Series
A1: Mindtickle Series Creation Template v1
A3: Series Name | B3: Black Belt WebEx Contact Center Enterprise Support Stage 2 | C3: Duration (mins) | D3: 176 | E3: Tile Image URL | F3: =HYPERLINK(INDEX(Input!Q1:U15,MATCH(Series!$B$11,Input!Q1:Q15,0),MATCH($D$7,Input!Q1:U1,0))) -> https://myciscosalesconnect.file.force.com/sfc/dist/version/download/?oid=00D8c000005u363&ids=0688c00000Dbzp6&d=%2Fa%2F8c000000gIUx%2FQfLjO1Zq4Yr8KHWaow7trnvEFMhqgOxgz6rnIeXWZB8&asPdf=false | G3: Anshul
A5: Description | B5: This training is designed to equip participants with advanced knowledge and skills required to support and troubleshoot WebEx Contact Center Enterprise solutions. | C5: Language | D5: English | E5: Pre-requisite | F5: Black Belt Support Stage 1
A7: About | C7: Stage | D7: 2 | E7: Next Best Training
A9: Default Language LP | C9: Authors | D9: amashar2, avatts, pugandhi | E9: =IF(OR($D$7=2,$D$7=3),"SG Form Link","") -> SG Form Link
A11: Architecture | B11: Collaboration | C11: End Date | D11: 46142 | E11: Sharing Rules | F11: All Partners
A14: Order | B14: Record Type | C14: Module Name | D14: Module Link (either Sharepoint or MT links) | E14: Module Description | F14: Module Duration (in mins)
A15: Section 1 | B15: Overview | C15: Mandatory | D15: Section Description (if any)
A16: 1 | B16: Media | C16: Webex_Contact_Center_Enterprise_Overview | D16: https://cisco.sharepoint.com/:f:/r/Sites/CiscoBlackBeltPartnerAcademy/Shared%20Documents/Mindtickle%20Publishing/Black%20Belt%20WebEx%20Contact%20Center%20Enterprise%20Support%20Stage%202?csf=1&web=1&e=RWCisW | E16: 58
A18: Section 2 | B18: What's New | C18: Mandatory
A19: 1 | B19: HTML | C19: What's New in Webex Contact Center Enterprise | D19: https://help.webex.com/en-us/article/nhy3hvdb/What's-New-in-Webex-Contact-Center-Enterprise | E19: 10
A21: Section 3 | B21: WebEx CCE Deployment Guide | C21: Mandatory
A22: 1 | B22: HTML | C22: Webex_Contact_Center_Enterprise_Quick_Deployment_Solution | D22: https://help.webex.com/en-us/article/nyosarq/Webex-Contact-Center-Enterprise-Quick-Deployment-Solution | E22: 10
A23: 2 | B23: Media | C23: Webex_Contact_Center_Enterprise_Admin_Portal_-_5_minute_demo_series | D23: https://video.cisco.com/detail/video/6200227780001?autoStart=true&q=webex%20contact%20center | E23: 6
A25: Section 4 | B25: Partner Technical Guide | C25: Mandatory
A26: 1 | B26: Media | C26: Cisco_Webex_Contact_Center_Enterprise_-_Partner_Technical_Guide | D26: https://cisco.sharepoint.com/:f:/r/Sites/CiscoBlackBeltPartnerAcademy/Shared%20Documents/Mindtickle%20Publishing/Black%20Belt%20WebEx%20Contact%20Center%20Enterprise%20Support%20Stage%202?csf=1&web=1&e=CfYyAq | E26: 10
A28: Section 5 | B28: Understanding Cloud and On-prem WebEx CCE | C28: Mandatory
A29: 1 | B29: Media | C29: Part 1 Understanding Cisco Private Cloud Contact Center Enterprise offering WCCE | D29: https://cisco.sharepoint.com/:f:/r/Sites/CiscoBlackBeltPartnerAcademy/Shared%20Documents/Editing%20Studio/Output/Understanding%20Cisco%20Private%20Cloud%20Contact%20Center%20Enterprise%20offering%20WCCE?csf=1&web=1&e=VzEFQm | E29: 15
A30: 2 | B30: Media | C30: Part 2 Understanding Cisco Private Cloud Contact Center Enterprise offering WCCE | D30: https://cisco.sharepoint.com/:f:/r/Sites/CiscoBlackBeltPartnerAcademy/Shared%20Documents/Editing%20Studio/Output/Understanding%20Cisco%20Private%20Cloud%20Contact%20Center%20Enterprise%20offering%20WCCE?csf=1&web=1&e=VzEFQm | E30: 22
A31: 3 | B31: Media | C31: Part 3 Understanding Cisco Private Cloud Contact Center Enterprise offering WCCE | D31: https://cisco.sharepoint.com/:f:/r/Sites/CiscoBlackBeltPartnerAcademy/Shared%20Documents/Editing%20Studio/Output/Understanding%20Cisco%20Private%20Cloud%20Contact%20Center%20Enterprise%20offering%20WCCE?csf=1&web=1&e=VzEFQm | E31: 15
A32: 4 | B32: Media | C32: Part 4 Understanding Cisco Private Cloud Contact Center Enterprise offering WCCE | D32: https://cisco.sharepoint.com/:f:/r/Sites/CiscoBlackBeltPartnerAcademy/Shared%20Documents/Editing%20Studio/Output/Understanding%20Cisco%20Private%20Cloud%20Contact%20Center%20Enterprise%20offering%20WCCE?csf=1&web=1&e=VzEFQm | E32: 20
A34: Section 6 | B34: Black Belt WebEx Contact Center Enterprise Support Stage 2 Quiz | C34: Mandatory
A35: 1 | B35: Quiz | C35: WebEx_Contact_Center_Enterprise_Support_Stage_2_Quiz | D35: https://cisco.sharepoint.com/:f:/r/Sites/CiscoBlackBeltPartnerAcademy/Shared%20Documents/Mindtickle%20Publishing/Black%20Belt%20WebEx%20Contact%20Center%20Enterprise%20Support%20Stage%202?csf=1&web=1&e=E2gWPZ | E35: 10
XEP1048570: Created by: Anshul Singh

Sheet Track
A1: Mindtickle Series Track Creation Template v1
A3: Series Track Name | B3: Black Belt | C3: Min Items for Completion | D3: 0 | E3: Background Image URL | G3: Anshul
A5: Description | C5: Pre-requisite
A7: Authors | B7: anshulsi, tepatil | C7: LMS Sharing Rules | D7: All Partners
A10: Track Level Order | B10: Track Level Name | C10: Series (1) | D10: Series (2) | E10: Series (3) | F10: Series (4) | G10: Series (5) | H10: Series (6) | I10: Series (7) | J10: Series (8) | K10: Series (9) | L10: Series (10)
A11: =IF(ISBLANK(Track!$B11),"",ROW()-10) -> 1 | B11: Sample Level 1 (This is a template, download and use)
A12: =IF(ISBLANK(Track!$B12),"",ROW()-10) -> 2 | B12: Sample Level 2
A13: =IF(ISBLANK(Track!$B13),"",ROW()-10) -> 3 | B13: Sample Level 3
A14: =IF(ISBLANK(Track!$B14),"",ROW()-10)
A15: =IF(ISBLANK(Track!$B15),"",ROW()-10)
A16: =IF(ISBLANK(Track!$B16),"",ROW()-10)
A17: =IF(ISBLANK(Track!$B17),"",ROW()-10)
A18: =IF(ISBLANK(Track!$B18),"",ROW()-10)
A19: =IF(ISBLANK(Track!$B19),"",ROW()-10)
A20: =IF(ISBLANK(Track!$B20),"",ROW()-10)
A21: =IF(ISBLANK(Track!$B21),"",ROW()-10)
A22: =IF(ISBLANK(Track!$B22),"",ROW()-10)
A23: =IF(ISBLANK(Track!$B23),"",ROW()-10)
A24: =IF(ISBLANK(Track!$B24),"",ROW()-10)
A25: =IF(ISBLANK(Track!$B25),"",ROW()-10)
... A50: =IF(ISBLANK(Track!$B50),"",ROW()-10)
XEP1048570: Created by: Anshul Singh

Sheet Guidelines
A1: Mindtickle Intake Guidelines v1
B2: *** | C2: Turn Around Time (TAT) | D2: For any publishing request (assessment, series, modules), the TAT is 5 business days. Approved critical/urgent request would take 2 business days per request.
B3: 1 | C3: Naming the intake template | D3: Nomenclature for intake template is, the date (yymmdd) followed by the Title (depending on the use case). Use underscore for word separation instead of spaces (special characters must not be used). Date could range from the template creation to template submission day. For assessments & track, template name must have the word 'Quiz' & 'Track' in it respectively. For eg: a.) Assessment Title: Browser Synthetics - ES Template name becomes: 230501_Browser_Synthetics_ES_Quiz Assessment Title: Black Belt - MDS - Presales - Stage 2 Quiz 3 Template name becomes: 230501_Black_Belt_MDS_Presales_Stage_2_Quiz_3 b.) Series Name: Black Belt Distribution Stage 1 AppDynamics Template name becomes: 230501_Black_Belt_Distribution_Stage_1_AppDynamics c.) Series Track Name: Black Belt Distribution Sales Specialist Stage 2 Template name becomes: 230801_Black_Belt_Distribution_Sales_Specialist_Stage_2_Track
B4: 2 | C4: Mandatory information | D4: Any field with RED font is a must requirement.
B5: 3 | C5: Assessment intake:-
B6: i | C6: Assessment Title | D6: Has a character limit of 100. Anything beyond the limit will not be published. Recommended Assessment title: 'Section Header' followed by '- Quiz'.
B7: ii | C7: Description | D7: Assessment description must be within 1000 characters max.
B8: iii | C8: Additional Information | D8: If the quiz description is beyond 255 characters, use this field. If using this field, least criteria is 11 characters.
B9: iv | C9: Quiz Page Name | D9: If not provided, default will be 'Page 01'. All the questions will be displayed on one page only. (max 80 characters)
B10: v | C10: Description | D10: Below Quiz Page name is the field for it's Description. Mention the Quiz page description (if any, max 255 characters). If using this field, least criteria is 11 characters.
B11: vi | C11: Duration | D11: It is auto calculated as per the number of Question Display Count. 2 mins per question.
B12: vii | C12: Language | D12: Select as applicable from the Drop Down list.
B13: viii | C13: Passing Score | D13: Must be a number from 1 to 100. Default passing score is 80%.
B14: ix | C14: Authors | D14: Must be Cisco ID. Comma separated for multiple authors. For eg: anshulsi, tepatil
B15: x | C15: Background Image URL | D15: For use, publishing team only.
B16: xi | C16: Content Trace ID | D16: For use, publishing team only.
B17: xii | C17: Content Source | D17: Mention the source of the content (if any).
... B26: *** | C26: Assessment Form | D26: Fill in the Assessment Publishing form (https://cs.co/BBAQuizv1).
B27: 4 | C27: Series intake:-
B28: i | C28: Series Name | D28: Has a character limit of 100. Anything beyond the limit will not be published.
B29: ii | C29: Description | D29: Series description must be within 1000 characters max.
B30: iii | C30: About | D30: If the Learning Plan description is beyond 255 characters, use this field. This is displayed in continuation to description so can be used in sync with it. If using this field, least criteria is 11 characters.
B31: iv | C31: Default Language LP | D31: For only localized Series, mention the English Series Name here.
B32: v | C32: Architecture | D32: Select as applicable from the Drop Down list.
B33: vi | C33: Duration | D33: Mention the duration of the Series considering only Mandatory Modules. Must be in minutes only.
B34: vii | C34: Language | D34: Select as applicable from the Drop Down list.
B35: viii | C35: Stage | D35: Select as applicable from the Drop Down list.
B36: ix | C36: Authors | D36: Must be Cisco ID. Comma separated for multiple authors. For eg: anshulsi, tepatil
B37: x | C37: End Date | D37: Expiry date of the Learning Plan.
B38: xi | C38: Background Image URL | D38: For use, publishing team only.
B39: xii | C39: Pre-requisite | D39: Mention the Series name, comma separated for more than one.
... B54: *** | C54: Series Form | D54: Fill in the Series Publishing form (https://cs.co/BBALPlanv1).
B55: 5 | C55: Series Track intake:-
B56: i | C56: Series Track Name | D56: Has a character limit of 100. Anything beyond the limit will not be published.
B57: ii | C57: Description | D57: Series Track description must be within 1000 characters max.
B58: iii | C58: Authors | D58: Must be Cisco ID. Comma separated for multiple authors. For eg: anshulsi, tepatil
B59: iv | C59: Minimum Items for Completion | D59: Mention the number of minimum items to complete for Track Achievement.
B60: v | C60: Pre-requisite | D60: Mention the Series name, comma separated for more than one.
B61: vi | C61: LMS Sharing Rules | D61: Entitlement for the content, select from the drop down list. List is downward inclusive. For eg: All Partners will include All Employees, All Distributors & All Partners.
B62: *** | C62: Series Track Template | D62: Upload the accurately filled template in a folder named after the series to which it belongs in Mindtickle Publishing folder.
...

Sheet Input
A1: Q Type | C1: Additional Information | E1: Language | G1: Correct Answer | I1: Stage | K1: Architecture | M1: Section Type | O1: Record Type | Q1: Architecture | R1: 1 | S1: 2 | T1: 3 | U1: On Going | W1: Cisco IDs
A2: Multiple Choice | C2: All Employees | E2: English | G2: Yes | I2: 1 | K2: 5G | M2: Mandatory | O2: Video | Q2: 5G | W2: aawoland
A3: Single Choice | C3: All Distributors | E3: Chinese (Simplified) | G3: No | I3: 2 | K3: Cisco Designed | M3: Optional | O3: Document | Q3: Cisco Designed | R3: https://myciscosalesconnect.file.force.com/sfc/dist/version/download/?oid=00D8c000005u363&ids=0688c00000Dbw6V&d=%2Fa%2F8c000000gINy%2FsbG6gX4hzBxaA9mj9Lp0ZWgTT2rC640C4grJXVp2qco&asPdf=false | S3: https://myciscosalesconnect.file.force.com/sfc/dist/version/download/?oid=00D8c000005u363&ids=0688c00000DbzvF&d=%2Fa%2F8c000000gIUy%2FlSj5StH0Xbs44izt8XeDP9502Wrw2CZisYspBLvvcYU&asPdf=false | W3: abhinsi8
A4: True/False | C4: All Partners | E4: French | I4: 3 | K4: Collaboration | M4: Reference Material | O4: PDF | Q4: Collaboration | R4: https://myciscosalesconnect.file.force.com/sfc/dist/version/download/?oid=00D8c000005u363&ids=0688c00000Dbzq9&d=%2Fa%2F8c000000gIVj%2FVhHu_LkRw6HuCoFvzSxu9PG2n8k_z_JCqV6B6ScLtwE&asPdf=false | S4: https://myciscosalesconnect.file.force.com/sfc/dist/version/download/?oid=00D8c000005u363&ids=0688c00000Dbzp6&d=%2Fa%2F8c000000gIUx%2FQfLjO1Zq4Yr8KHWaow7trnvEFMhqgOxgz6rnIeXWZB8&asPdf=false | T4: https://myciscosalesconnect.file.force.com/sfc/dist/version/download/?oid=00D8c000005u363&ids=0688c00000Dbvdz&d=%2Fa%2F8c000000gIL9%2FKl7HkaF9Vit3yjLqOem2Z7O_wNfEkIC0c6hX.Tbl9lk&asPdf=false | W4: abkarve
E5: German | I5: On Going | K5: Cross Architecture | O5: Assessment | Q5: Cross Architecture | R5: https://myciscosalesconnect.file.force.com/sfc/dist/version/download/?oid=00D8c000005u363&ids=0688c00000DcCC6&d=%2Fa%2F8c000000gJ0H%2FF.f6QrPJAHhBtli2c_qef7viv_dbAd_nUumuaL83.n0&asPdf=false | S5: https://myciscosalesconnect.file.force.com/sfc/dist/version/download/?oid=00D8c000005u363&ids=0688c00000DcXSn&d=%2Fa%2F8c000000gJTj%2FPvoVxMKM4cuJqPzMeTsd44qe7RBUltr3obYbpWIYsmA&asPdf=false | W5: ajoshi3
E6: Italian | K6: Data Center | O6: Case Study | Q6: Data Center | R6: https://myciscosalesconnect.file.force.com/sfc/dist/version/download/?oid=00D8c000005u363&ids=0688c00000Dc00j&d=%2Fa%2F8c000000gIW4%2Fb318Xb1BcwJWplyzKF_JD4huu7Zp_T6_DEQdH3ErTBE&asPdf=false | S6: https://myciscosalesconnect.file.force.com/sfc/dist/version/download/?oid=00D8c000005u363&ids=0688c00000Dc1AP&d=%2Fa%2F8c000000gIhA%2FedFadZDlFEQ7bTNnOW21K8OfoopE0os7ix4IABWqWYQ&asPdf=false | T6: https://myciscosalesconnect.file.force.com/sfc/dist/version/download/?oid=00D8c000005u363&ids=0688c00000Dc0pt&d=%2Fa%2F8c000000gIcW%2FhZfVzcoauxTYx4X0hZpjh_auH.8s0UM2gGHb7gZZHGI&asPdf=false | W6: alafever
E7: Japanese | K7: Devnet | O7: CTF | Q7: Devnet | R7: https://myciscosalesconnect.file.force.com/sfc/dist/version/download/?oid=00D8c000005u363&ids=0688c00000Dc09k&d=%2Fa%2F8c000000gIXA%2FJeHbkluS_YhsAtJvBmm6OLz6TQGHqxWB7bp1s3n.Lko&asPdf=false | S7: https://myciscosalesconnect.file.force.com/sfc/dist/version/download/?oid=00D8c000005u363&ids=0688c00000Dc12a&d=%2Fa%2F8c000000gIdi%2FGFkNWsXbkWoHcN_TpwnA3KR_qVgf78NhPw0QPGLlf7s&asPdf=false | T7: https://myciscosalesconnect.file.force.com/sfc/dist/version/download/?oid=00D8c000005u363&ids=0688c00000Dc12g&d=%2Fa%2F8c000000gIdo%2Fw_orJJs.xZmu9Hp2sEE6INT8.EMqjqVIRV5iwAImHyY&asPdf=false | W7: alejrodr
E8: Korean | K8: Enterprise Networks | O8: dCloud | Q8: Enterprise Networks | R8: https://myciscosalesconnect.file.force.com/sfc/dist/version/download/?oid=00D8c000005u363&ids=0688c00000Dc6ok&d=%2Fa%2F8c000000gIqi%2F3DjfBJBpRPZMgnNRlTPHzHSOQXgre0V499gp7ENEBeE&asPdf=false | S8: https://myciscosalesconnect.file.force.com/sfc/dist/version/download/?oid=00D8c000005u363&ids=0688c00000Dbzqp&d=%2Fa%2F8c000000gIVF%2FQtT0d4pbdymw.3tthKq.kR99ir6MPcEBuGhzEEwa32g&asPdf=false | T8: https://myciscosalesconnect.file.force.com/sfc/dist/version/download/?oid=00D8c000005u363&ids=0688c00000Dc16b&d=%2Fa%2F8c000000gIfE%2F8.vyU169q9UUX0Ju8IeyysN0.uIBeZnMqlIAFffAVdI&asPdf=false | W8: amashar2
E9: Portuguese (Brazil) | K9: IOT | O9: Deal ID | Q9: IOT | R9: https://myciscosalesconnect.file.force.com/sfc/dist/version/download/?oid=00D8c000005u363&ids=0688c00000Dc18j&d=%2Fa%2F8c000000gIgq%2FlM5Lnm2PFZaaJSfSEIoAYQA7XVF4Soz_6hnBkVOIpGM&asPdf=false | S9: https://myciscosalesconnect.file.force.com/sfc/dist/version/download/?oid=00D8c000005u363&ids=0688c00000DcCJT&d=%2Fa%2F8c000000gJ15%2FBz8TWhrlpimN6WbhjkFqp.wDKvAwyL5B_bLFxH75Rsk&asPdf=false | W9: amekulka
E10: Spanish (Mexico) | K10: Meraki | O10: Excel | Q10: Meraki | R10: https://myciscosalesconnect.file.force.com/sfc/dist/version/download/?oid=00D8c000005u363&ids=0688c00000Dc16Q&d=%2Fa%2F8c000000gIeo%2FNCIufPFGNmPRHFFRj5jhqwm_OQtjZuAQc2Xpvn9PPp0&asPdf=false | S10: https://myciscosalesconnect.file.force.com/sfc/dist/version/download/?oid=00D8c000005u363&ids=0688c00000Dbzyv&d=%2Fa%2F8c000000gIW6%2FXWZRkkIX.8qUQ2Tl3GC4ovTKI.VwNUJcjwuG1ZoxeVI&asPdf=false | T10: https://myciscosalesconnect.file.force.com/sfc/dist/version/download/?oid=00D8c000005u363&ids=0688c00000DcCH4&d=%2Fa%2F8c000000gJ0v%2FeYJ_2rCpVD5OcMmYi9u4ovuPc7CfnQbJf8tIHf8HYRQ&asPdf=false | W10: amyedwar
E11: Thai | K11: Multi Domain | O11: HLD LLD | Q11: Multi Domain | R11: https://myciscosalesconnect.file.force.com/sfc/dist/version/download/?oid=00D8c000005u363&ids=0688c00000Dbzyw&d=%2Fa%2F8c000000gIVk%2F.8RUTXu.ZYyg9ytl27rGoiU4Oah9GBfp.7_JA1NQevE&asPdf=false | S11: https://myciscosalesconnect.file.force.com/sfc/dist/version/download/?oid=00D8c000005u363&ids=0688c00000Dc6nb&d=%2Fa%2F8c000000gIqN%2F9m_3_R0kquZkNPWbnAoRNv51kNAQscrNDO8_LQvUFmA&asPdf=false | T11: https://myciscosalesconnect.file.force.com/sfc/dist/version/download/?oid=00D8c000005u363&ids=0688c00000DcC5L&d=%2Fa%2F8c000000gIz9%2FZNxIFXNhXokmEdd5GYmGf1IJywZ0QfMl9TieJgz9zF4&asPdf=false | W11: anantku
E12: Vietnamese | K12: Non Architecture | O12: HTML | Q12: Non Architecture | R12: https://myciscosalesconnect.file.force.com/sfc/dist/version/download/?oid=00D8c000005u363&ids=0688c00000Dc6o5&d=%2Fa%2F8c000000gIqb%2FQRWM.V7wf9JxgRglUXJO7A_vlXa5Kkl4w.LfO_lu5OE&asPdf=false | S12: https://myciscosalesconnect.file.force.com/sfc/dist/version/download/?oid=00D8c000005u363&ids=0688c00000DbzsW&d=%2Fa%2F8c000000gIVJ%2FYL0zH_2R34ULoj4RplPPVPlmv5bc7tsIJ61ylqq5rHs&asPdf=false | T12: https://myciscosalesconnect--c.documentforce.com/sfc/dist/version/download/?oid=00D8c000005u363&ids=0688c00000De9A5&d=%2Fa%2F8c000000gLCP%2FcR.AB4O6ofsjbNL5oBfe9dYg29Anitx6bkSfx8f_4YA&asPdf=false | W12: aneidlin
K13: Security | O13: Perfect Pitch | Q13: Security | R13: https://myciscosalesconnect.file.force.com/sfc/dist/version/download/?oid=00D8c000005u363&ids=0688c00000Dc1TF&d=%2Fa%2F8c000000gIkE%2Fx8sAM4Vop.NIQrcu9O0_3eYKtodQhRkeAKpbkTrMqko&asPdf=false | S13: https://myciscosalesconnect.file.force.com/sfc/dist/version/download/?oid=00D8c000005u363&ids=0688c00000Dc1RL&d=%2Fa%2F8c000000gIk6%2Fl75C0RLdpzqEW2_miZz7mwHb7_4yFjgAGMtZClWng.c&asPdf=false | T13: https://myciscosalesconnect.file.force.com/sfc/dist/version/download/?oid=00D8c000005u363&ids=0688c00000Dc6ne&d=%2Fa%2F8c000000gIrV%2Fvoz4fw35DrYkbjVHImAdSObdfKtk3QfEJyUpQWvgpaQ&asPdf=false | W13: annduong
K14: Service Provider | O14: Poll | Q14: Service Provider | S14: https://myciscosalesconnect.file.force.com/sfc/dist/version/download/?oid=00D8c000005u363&ids=0688c00000DcQx0&d=%2Fa%2F8c000000gJJb%2Fo9bbjPxEV3sgCC_oOWky7bvC3OajqbY8qzeUTELLFpw&asPdf=false | W14: anshulsi
K15: Other | O15: PPT | Q15: Other | W15: anskaush
O16: Scorm | W16: answami
O17: Sales Order | W17: anuniyal
O18: Survey | W18: ashmorga
W19: asugatha
W20: avatts
W21: bilclay
W22: bkanova
W23: brcuneo
W24: brfoster
W25: cbinz
W26: chclasen
W27: chmoreto
W28: chrjohn4
W29: cincampb
W30: ckayserc
... W113: yegowda
