Workbook
Name UpdateList: IF(#REF!="Valid",#REF!, "")
Name UpdateList: IF(Series!$AW$1="Valid", Series!$AV$2:$AV$4, "")
Name UpdateList: IF(#REF!="Valid",#REF!, "")

Sheet Series
A1: Mindtickle Series Template v2.4 | O1: Notes | AA1: Category (Architecture) | AC1: Program Track | AD1: PT to be used | AF1: Track | AH1: Persona | AJ1: role | AL1: bookings architecture | AN1: Language | AO1: Lang Code | AQ1: Business Entity | AR1: Business Sub-Entity | AT1: File Type | AV1: Update | AW1: =IF(J12="Update", "Valid", "Invalid") -> Invalid | AY1: Sub Criteria | BF1: File Type
AA2: Cloud + AI Infrastructure | AC2: 5G Mobility | AD2: 5G Mobility | AF2: Deployment | AH2: Cisco Internal | AJ2: Business Architect | AL2: Collaboration | AN2: English | AQ2: Cisco Compute | AR2: Hyper Converged | AT2: Doc | AV2: Add | AY2: Assessment | AZ2: =IF(OR($F$10="Stage 2",$F$10="Stage 3"),"Valid","Invalid") -> Valid | BF2: Prerequisite
B3: =CLEAN(TRIM(IF(B6="Generated", IF(OR(ISBLANK(B10),ISBLANK(D10),ISBLANK(F10),ISBLANK(H10),ISBLANK(J10)), "", _xlfn.CONCAT( IF(H10="Distributor", "Black Belt Distribution ", "Black Belt "), VLOOKUP(B10,$AC:$AD,2,0), " ", D10, " ", F10, IF(J10="English", "", " "&VLOOKUP(J10,$AN$2:$AO$9,2,0)), " (", TEXT(TODAY(), "MMM YYYY"), ")" )),D6))) -> Black Belt ASA and Firewall Support Stage 3 (Dec 2025) | AA3: Collaboration | AC3: Access | AD3: Access | AF3: Pre-Sales | AH3: Distributor | AJ3: Channels | AL3: Data Center | AN3: Chinese | AO3: ZH | AQ3: Cisco Compute | AR3: Intersight | AT3: HTML | AV3: Modify | AY3: Case Study | AZ3: 1 | BA3: =IF(#REF!>=AZ3,"Valid","Invalid") -> #REF! | BF3: Mission: Case Study
B4: =IF(OR(ISBLANK($B$12), ISBLANK($B$8)), "", CLEAN(TRIM($B$8)) & CHAR(10) & IF(B12>59, "Estimated series completion duration: " & INT(B12/60) & " h " & MOD(B12, 60) & " m","Estimated series completion duration: "&B12&" m")) -> This Learning Series equips partners with trainings to effectively design and position Cisco's cutting edge Switching solutions and capabilities for the AI era. Estimated series completion duration: 3 h 42 m | AA4: Cross Architecture | AC4: Access and Endpoints | AD4: Access and Endpoints | AF4: Sales | AH4: Partner | AJ4: Customer Experience | AL4: DevNet | AN4: German | AO4: DE | AQ4: Cisco Compute | AR4: Servers | AT4: PDF | AV4: Remove | AY4: CTF | AZ4: 2 | BA4: =IF(#REF!>=AZ4,"Valid","Invalid") -> #REF! | BB4: {=IF($BA4="Valid",_xlfn._xlws.FILTER($AY$3:$AY$7, $AY$3:$AY$7<>B16),"")} -> #REF! | BF4: Mission: CTF
AA5: DevNet | AC5: Advanced Threat | AD5: Advanced Threat | AF5: Support | AJ5: Engineering | AL5: IoT | AN5: Japanese | AO5: JA | AQ5: Collaboration | AR5: Cloud Contact Center | AT5: PPT | AY5: dCloud | AZ5: 3 | BA5: =IF(#REF!>=AZ5,"Valid","Invalid") -> #REF! | BC5: {=IF(BA5="Valid",_xlfn._xlws.FILTER($AY$3:$AY$7, ($AY$3:$AY$7<>B16)*($AY$3:$AY$7<>C16)),"")} -> #REF! | BF5: Mission: dCloud
A6: Series Title | B6: Manual | C6: =IF(B6="Manual","Custom Title","") -> Custom Title | D6: Black Belt ASA and Firewall Support Stage 3 (Dec 2025) | AA6: Internet & Mass Scale Infra | AC6: AI Data Fundamentals | AD6: AI Data Fundamentals | AF6: AWS-CPPO | AJ6: Marketeer | AL6: ISG | AN6: Korean | AO6: KO | AQ6: Collaboration | AR6: Cloud Webex Suite | AT6: SCORM | AY6: HLD LLD | AZ6: 4 | BA6: =IF(#REF!>=AZ6,"Valid","Invalid") -> #REF! | BD6: {=IF(BA6="Valid",_xlfn._xlws.FILTER($AY$3:$AY$7, ($AY$3:$AY$7<>B16)*($AY$3:$AY$7<>C16)*($AY$3:$AY$7<>D16)),"")} -> #REF! | BF6: Mission: HLD LLD
AA7: Networking | AC7: AI Defense | AD7: AI Defense | AF7: BA | AJ7: New Hire | AL7: Meraki | AN7: Portuguese | AO7: PT | AQ7: Collaboration | AR7: CPaaS | AT7: Video | AY7: Perfect Pitch | AZ7: 5 | BA7: =IF(#REF!=AZ7,"Valid","Invalid") -> #REF! | BE7: {=IF(BA7="Valid",_xlfn._xlws.FILTER($AY$3:$AY$7, ($AY$3:$AY$7<>B16)*($AY$3:$AY$7<>C16)*($AY$3:$AY$7<>D16)*($AY$3:$AY$7<>E16)),"")} -> #REF! | BF7: Mission: Perfect Pitch
A8: Description | B8: This Learning Series equips partners with trainings to effectively design and position Cisco's cutting edge Switching solutions and capabilities for the AI era. | AA8: Non Architecture | AC8: AI Fabric Design | AD8: AI Fabric Design | AF8: COVID | AJ8: Operations | AL8: Network Experience | AN8: Spanish | AO8: ES | AQ8: Collaboration | AR8: On-Prem Contact Center | AT8: Assessment
AA9: Security | AC9: AI Fundamentals | AD9: AI Fundamentals | AF9: CX | AJ9: PAMs, vPAMs, DAMs | AL9: Other | AN9: Thai | AO9: TH | AQ9: Collaboration | AR9: On-Prem Webex Suite
A10: Program Track | B10: ASA and Firewall | C10: Track | D10: Support | E10: Stage | F10: Stage 3 | G10: Persona | H10: Partner | I10: Language | J10: English | AA10: Services | AC10: AI Ready Infrastructure | AD10: AI Ready Infrastructure | AF10: Developer | AJ10: Partner Transformation | AL10: Security | AQ10: Collaboration | AR10: Other
AA11: SMB | AC11: AppDynamics | AD11: AppDynamics | AF11: Marketeer | AJ11: Sales | AL11: Service Provider | AQ11: Collaboration | AR11: Phone and Headset Devices
A12: Duration (mins) | B12: 222 | C12: BE | D12: Security | E12: Sub BE | F12: Network Security | G12: Category | H12: Security | I12: Request Type | J12: New | AA12: Splunk | AC12: Application Centric Infrastructure (ACI) | AD12: ACI | AF12: New Hire | AJ12: X-Sell | AL12: X-Sell | AQ12: Collaboration | AR12: Video Devices
AC13: Application Experience and Management | AD13: Application Experience and Management | AF13: Operations | AQ13: Data Center Networking | AR13: Acacia - DC Allocation
A14: Series Owners | B14: anshulsi | C14: Certificate | D14: Yes | E14: Checkpoints | F14: =( IF(B6<>"", 1, 0) + IF(D6<>"", 1, 0) + IF(B8<>"", 1, 0) + IF(B10<>"", 1, 0) + IF(D10<>"", 1, 0) + IF(F10<>"", 1, 0) + IF(H10<>"", 1, 0) + IF(J10<>"", 1, 0) + IF(B12<>"", 1, 0) + IF(D12<>"", 1, 0) + IF(F12<>"", 1, 0) + IF(H12<>"", 1, 0) + IF(J12<>"", 1, 0) + IF(B14<>"", 1, 0) + IF(D14<>"", 1, 0)+ IF(B16<>"", 1, 0)+ IF(F16<>"", 1, 0) ) & "/" & ( IF(B6="Generated", 16, 0) + IF(B6="Manual", 17, 0) ) -> 17/17 | G14: Folder Name | H14: =IF(LEN(B3)<2, "", CLEAN(TRIM(SUBSTITUTE(SUBSTITUTE(SUBSTITUTE(SUBSTITUTE(B3, " ", "_"), "/", "_"), "\", "_"), ":", "_")))) -> Black_Belt_ASA_and_Firewall_Support_Stage_3_(Dec_2025) | I14: Template Name | J14: =IF(LEN(B3)<2,"",TEXT(TODAY(),"YYMMDD")&_xlfn.CONCAT("_",SUBSTITUTE(SUBSTITUTE(SUBSTITUTE(SUBSTITUTE(B3, " ", "_"), "/", "_"), "\", "_"), ":", "_"))) -> 251215_Black_Belt_ASA_and_Firewall_Support_Stage_3_(Dec_2025) | AC14: Application First Security | AD14: Application First Security | AF14: PAM | AQ14: Data Center Networking | AR14: NX1K
AC15: AR/VR | AD15: AR/VR | AF15: Practice Development | AQ15: Data Center Networking | AR15: NX2/4/5/6K
A16: P360 | B16: No | C16: Request Form | D16: cs.co/BBASP | E16: Refresh or New | F16: Refresh | AC16: ASA and Firewall | AD16: ASA and Firewall | AF16: SBPS | AQ16: Data Center Networking | AR16: NX3K
AC17: Attack Surface Management | AD17: Attack Surface Management | AF17: X-Sell CSS | AQ17: Data Center Networking | AR17: NX7K
A18: =COUNTA(_xlfn.UNIQUE($A$20:$A$103))-1 -> 5 | B18: =COUNTA(_xlfn.UNIQUE($B$20:$B$103))-1 -> 5 | C18: =COUNTA($C$20:$C$103) -> 11 | D18: =COUNTA($D$20:$D$103) -> 11 | E18: =COUNTA($E$20:$E$103) -> 11 | F18: =COUNTA(_xlfn.UNIQUE($F$20:$F$103))-1 -> 11 | G18: =COUNTA($G$20:$G$103)+COUNTIFS($K$20:$K$103, "<>", $K$20:$K$103, "<>*sharepoint*")-COUNTIF($E$20:$E$103, "*HTML*") -> 11 | H18: =COUNTA($H$20:$H$103)+COUNTIFS($K$20:$K$103, "<>", $K$20:$K$103, "<>*sharepoint*")-COUNTIF($E$20:$E$103, "*HTML*") -> 11 | I18: =COUNTA($I$20:$I$103) -> 11 | J18: =COUNTA(_xlfn.UNIQUE($J$20:$J$103))+COUNTIFS($K$20:$K$103, "<>", $K$20:$K$103, "<>*sharepoint*")-COUNTIF($E$20:$E$103, "*HTML*")-1 -> 11 | K18: =COUNTA($K$20:$K$103) -> 11 | L18: =IF($J$12="Update",COUNTA($L$20:$L$103),"") | AC18: Automation and Insights | AD18: Automation and Insights | AF18: X-Sell SBPS | AQ18: Data Center Networking | AR18: NX8K
A19: Section Order | B19: Section Name | C19: Section (M/O) | D19: Module Order | E19: Module Type | F19: Module Title | G19: Duration (mins) | H19: Module Description | I19: Module (M/O) | J19: Module File Name | K19: Module Link | L19: =IF(J12="Update","Update","") | AC19: BCS DIL | AD19: BCS DIL | AF19: X-Sell TIS | AQ19: Data Center Networking | AR19: NX9K
A20: 1 | B20: ASA to NGFW Migration | C20: Mandatory | D20: 1 | E20: Video | F20: Part 1 Endtoend Asa To Ngfw Migration | G20: 21 | H20: This video will provide you insights on ASA migration | I20: Mandatory | J20: Part 1 EndtoEnd_ASA_to_NGFW_Migration.mp4 | K20: https://cisco.sharepoint.com/:v:/r/Sites/CiscoBlackBeltPartnerAcademy/Shared%20Documents/Mindtickle%20Publishing/Black_Belt_ASA_and_Firewall_Support_Stage_3_(Jun_2025)/Part%201%20Keeping_Up_on_Network_Security_with_Cisco_Secure_Firewall.mp4?csf=1&web=1&e=lAZ9rO | AC20: Business Architecture | AD20: Business Architecture | AQ20: Data Center Networking | AR20: Optics - DC Allocation
A21: 1 | B21: ASA to NGFW Migration | C21: Mandatory | D21: 2 | E21: Video | F21: Part 2 Endtoend Asa To Ngfw Migration | G21: 23 | H21: This video will provide you insights on ASA migration | I21: Mandatory | J21: Part 2 EndtoEnd_ASA_to_NGFW_Migration.mp4 | K21: https://cisco.sharepoint.com/:v:/r/Sites/CiscoBlackBeltPartnerAcademy/Shared%20Documents/Mindtickle%20Publishing/Black_Belt_ASA_and_Firewall_Support_Stage_3_(Jun_2025)/Part%201%20Keeping_Up_on_Network_Security_with_Cisco_Secure_Firewall.mp4?csf=1&web=1&e=lAZ9rO | AC21: Business Continuity | AD21: Business Continuity | AQ21: Data Center Networking | AR21: Other Data Center
A22: 2 | B22: Cisco Secure Firewall | C22: Mandatory | D22: 1 | E22: Video | F22: Part 1 Keeping Up On Network Security With Cisco Secure Firewall | G22: 18 | H22: This video will provide you insights on Cisco Secure firewall | I22: Mandatory | J22: Part 1 Keeping_Up_on_Network_Security_with_Cisco_Secure_Firewall.mp4 | K22: https://cisco.sharepoint.com/:v:/r/Sites/CiscoBlackBeltPartnerAcademy/Shared%20Documents/Mindtickle%20Publishing/Black_Belt_ASA_and_Firewall_Support_Stage_3_(Jun_2025)/Part%201%20Keeping_Up_on_Network_Security_with_Cisco_Secure_Firewall.mp4?csf=1&web=1&e=lAZ9rO | AC22: Business Critical Services | AD22: Business Critical Services | AQ22: Data Center Networking | AR22: SAN
A23: 2 | B23: Cisco Secure Firewall | C23: Mandatory | D23: 2 | E23: Video | F23: Part 2 Keeping Up On Network Security With Cisco Secure Firewall | G23: 19 | H23: This video will provide you insights on Cisco Secure firewall | I23: Mandatory | J23: Part 2 Keeping_Up_on_Network_Security_with_Cisco_Secure_Firewall.mp4 | K23: https://cisco.sharepoint.com/:v:/r/Sites/CiscoBlackBeltPartnerAcademy/Shared%20Documents/Mindtickle%20Publishing/Black_Belt_ASA_and_Firewall_Support_Stage_3_(Jun_2025)/Part%201%20Keeping_Up_on_Network_Security_with_Cisco_Secure_Firewall.mp4?csf=1&web=1&e=lAZ9rO | AC23: Business Edition 4K/6K/7K | AD23: Business Edition 4K/6K/7K | AQ23: Enterprise Routing | AR23: Ent. Access Routing
A24: 3 | B24: Enhanced Application Visibility | C24: Mandatory | D24: 1 | E24: Video | F24: Part 1 Enhanced Application Visibility Video | G24: 22 | H24: This video talks about Enhanced application visibility | I24: Mandatory | J24: Part 1 Enhanced_Application_Visibility_video.mp4 | K24: https://cisco.sharepoint.com/:v:/r/Sites/CiscoBlackBeltPartnerAcademy/Shared%20Documents/Mindtickle%20Publishing/Black_Belt_ASA_and_Firewall_Support_Stage_3_(Jun_2025)/Part%201%20Keeping_Up_on_Network_Security_with_Cisco_Secure_Firewall.mp4?csf=1&web=1&e=lAZ9rO | AC24: Business Edition 6K/7K | AD24: Business Edition 6K/7K | AQ24: Enterprise Routing | AR24: Ent. Edge Routing
A25: 3 | B25: Enhanced Application Visibility | C25: Mandatory | D25: 2 | E25: Video | F25: Part 2 Enhanced Application Visibility Video | G25: 22 | H25: This video talks about Enhanced application visibility | I25: Mandatory | J25: Part 2 Enhanced_Application_Visibility_video.mp4 | K25: https://cisco.sharepoint.com/:v:/r/Sites/CiscoBlackBeltPartnerAcademy/Shared%20Documents/Mindtickle%20Publishing/Black_Belt_ASA_and_Firewall_Support_Stage_3_(Jun_2025)/Part%201%20Keeping_Up_on_Network_Security_with_Cisco_Secure_Firewall.mp4?csf=1&web=1&e=lAZ9rO | AC25: Business Resiliency | AD25: Business Resiliency | AQ25: Enterprise Routing | AR25: Ent. Cloud Platforms
A26: 4 | B26: FTD Automation | C26: Mandatory | D26: 1 | E26: Video | F26: Part 1 Firepower Threat Defense Automation Using Apis | G26: 16 | H26: This video talks about FTD automation using APIs | I26: Mandatory | J26: Part 1 FirePower_Threat_Defense_Automation_using_APIs.mp4 | K26: https://cisco.sharepoint.com/:v:/r/Sites/CiscoBlackBeltPartnerAcademy/Shared%20Documents/Mindtickle%20Publishing/Black_Belt_ASA_and_Firewall_Support_Stage_3_(Jun_2025)/Part%201%20Keeping_Up_on_Network_Security_with_Cisco_Secure_Firewall.mp4?csf=1&web=1&e=lAZ9rO | AC26: Catalyst Center | AD26: Catalyst Center | AQ26: Enterprise Routing | AR26: IIoT Routing
A27: 4 | B27: FTD Automation | C27: Mandatory | D27: 2 | E27: Video | F27: Part 2 Firepower Threat Defense Automation Using Apis | G27: 19 | H27: This video talks about FTD automation using APIs | I27: Mandatory | J27: Part 2 FirePower_Threat_Defense_Automation_using_APIs.mp4 | K27: https://cisco.sharepoint.com/:v:/r/Sites/CiscoBlackBeltPartnerAcademy/Shared%20Documents/Mindtickle%20Publishing/Black_Belt_ASA_and_Firewall_Support_Stage_3_(Jun_2025)/Part%201%20Keeping_Up_on_Network_Security_with_Cisco_Secure_Firewall.mp4?csf=1&web=1&e=lAZ9rO | AC27: CCW Deal Manager | AD27: CCW Deal Manager | AQ27: Enterprise Routing | AR27: Meraki SD-WAN
A28: 4 | B28: FTD Automation | C28: Mandatory | D28: 3 | E28: Video | F28: Part 3 Firepower Threat Defense Automation Using Apis | G28: 19 | H28: This video talks about FTD automation using APIs | I28: Mandatory | J28: Part 3 FirePower_Threat_Defense_Automation_using_APIs.mp4 | K28: https://cisco.sharepoint.com/:v:/r/Sites/CiscoBlackBeltPartnerAcademy/Shared%20Documents/Mindtickle%20Publishing/Black_Belt_ASA_and_Firewall_Support_Stage_3_(Jun_2025)/Part%201%20Keeping_Up_on_Network_Security_with_Cisco_Secure_Firewall.mp4?csf=1&web=1&e=lAZ9rO | AC28: Cisco DNA | AD28: Cisco DNA | AQ28: Enterprise Switching | AR28: Ent. - Other
A29: 4 | B29: FTD Automation | C29: Mandatory | D29: 4 | E29: Video | F29: Part 4 Firepower Threat Defense Automation Using Apis | G29: 15 | H29: This video talks about FTD automation using APIs | I29: Mandatory | J29: Part 4 FirePower_Threat_Defense_Automation_using_APIs.mp4 | K29: https://cisco.sharepoint.com/:v:/r/Sites/CiscoBlackBeltPartnerAcademy/Shared%20Documents/Mindtickle%20Publishing/Black_Belt_ASA_and_Firewall_Support_Stage_3_(Jun_2025)/Part%201%20Keeping_Up_on_Network_Security_with_Cisco_Secure_Firewall.mp4?csf=1&web=1&e=lAZ9rO | AC29: Cisco Entity | AD29: Cisco Entity | AQ29: Enterprise Switching | AR29: Ent. Small Business - Switching
A30: 5 | B30: Black Belt Firewall Support Stage 3 Quiz | C30: Mandatory | D30: 1 | E30: Assessment | F30: Black Belt Firewall Support Stage 3 Quiz | G30: 28 | H30: This will test your knowledge on the topics covered in the learning series | I30: Mandatory | J30: 250625_Black_Belt_Firewall_Support_Stage_3_Quiz.xlsx | K30: https://cisco.sharepoint.com/:f:/r/Sites/CiscoBlackBeltPartnerAcademy/Shared%20Documents/Mindtickle%20Publishing/Assessment%20Template?csf=1&web=1&e=fICcJS | AC30: Cisco Meeting Servers | AD30: Cisco Meeting Servers | AQ30: Enterprise Switching | AR30: Ent. Switching - Access
AA31: Pre-Sales | AC31: Cisco Prime Migration | AD31: Cisco Prime Migration | AQ31: Enterprise Switching | AR31: Ent. Switching - Connected Platforms
AA32: Deployment | AC32: Cisco Secure Client | AD32: Cisco Secure Client | AQ32: Enterprise Switching | AR32: Ent. Switching - Core
AA33: Support | AC33: Cisco Spaces | AD33: Cisco Spaces | AQ33: Enterprise Switching | AR33: IIoT Switching
AA34: Sales | AC34: Cisco Umbrella | AD34: Cisco Umbrella | AQ34: Enterprise Switching | AR34: Meraki Switching
AA35: CX | AC35: Cisco Wearables and Peripherals | AD35: Cisco Wearables and Peripherals | AQ35: Enterprise Switching | AR35: Optics - Ent. Networking Allocation
AA36: Operations | AC36: Cisco+ Secure Connect | AD36: Cisco+ Secure Connect | AQ36: Enterprise Switching | AR36: Optics - IIoT Allocation
AA37: Marketeer | AC37: Cloud Analytics | AD37: Cloud Analytics | AQ37: Internet Infrastructure | AR37: Acacia - Internet Infra Allocation
AC38: Cloud Application Security | AD38: Cloud Application Security | AQ38: Internet Infrastructure | AR38: Automation
AC39: Cloud Calling | AD39: Cloud Calling | AQ39: Internet Infrastructure | AR39: Cable Access & Infra (CMTS, QAM, HFC)
AC40: Cloud Collaboration | AD40: Cloud Collaboration | AQ40: Internet Infrastructure | AR40: Control Center
...

Sheet Mis & Pre
A1: =IF(LEN(Series!$B$3)<5,"",_xlfn.CONCAT(Series!$B$3," Submission Guidelines")) -> Black Belt ASA and Firewall Support Stage 3 (Dec 2025) Submission Guidelines
A3: =_xlfn.CONCAT("M: ",COUNTIF($A$5:$A$33,"*Mission*")," P: ",COUNTIF($A$5:$A$33,"Prerequisite")) -> M: 1 P: 1 | B3: =COUNTA($B$5:$B$33) -> 2 | C3: {=_xlfn.UNIQUE(COUNTA($C$5:$C$33))-1} -> 2 | D3: =COUNTA($D$5:$D$33) -> 2 | E3: =COUNTIFS($A$5:$A$33, "*CTF*", $E$5:$E$33, "<>") + COUNTIFS($A$5:$A$33, "*dCloud*", $E$5:$E$33, "<>") + COUNTIFS($A$5:$A$33, "Prerequisite", $E$5:$E$33, "<>") -> 2
A4: Missions & Prerequisites | B4: Order | C4: Name | D4: Description | E4: Link
A5: Prerequisite | B5: 1 | C5: Black Belt Firewall Support Stage 2 | D5: In this Learning Plan you will have overview knowledge on Cisco ASA and NGFW firewalls and will also gain knowledge on some of the troubleshooting techniques to fix known issues. | E5: https://partnerlearning.cisco.com/new/ui/learner/training/programs/1887557633188225850?series=1887557633188225850
A6: Mission: CTF | B6: 2 | C6: Black Belt Support Firewall Stage 3 - Capture the Flag | D6: Cisco Firewall Capture the flag hands-on exercise event registration guide | E6: https://partnerlearning.cisco.com/new/ui/learner/update/1887844423334243741/consume?loId=1887844431002825615&topicId=1887844423429215343&series=1887557681994663812

Sheet Track
A1: Mindtickle Track Template
A3: Track Title | D3: Instruction Document | E3: Sharepoint Link for the document | G3: Notes
A5: Order | B5: Section Header | C5: Series Title | D5: Link | E5: Comments

Sheet Rename
A1: Series Title | B1: Template Name | C1: Publisher | D1: Language | E1: Status | F1: User Remarks | G1: Publishers Remarks | H1: Submissions | I1: Certificate | J1: Program Track | K1: Track | L1: Stage | M1: Persona | N1: Mapping Architecture | O1: Mapping Role | P1: BE : Sub BE | Q1: Replacement
A2: =Series!$B$3 -> Black Belt ASA and Firewall Support Stage 3 (Dec 2025) | D2: =Series!$J$10 -> English | E2: Complete | I2: =Series!$D$14 -> Yes | J2: =Series!$B$10 -> ASA and Firewall | K2: =Series!$D$10 -> Support | L2: =Series!$F$10 -> Stage 3 | M2: =Series!$H$10 -> Partner | N2: =Series!$H$12 -> Security | P2: =_xlfn.CONCAT(Series!$D$12," : ",Series!$F$12) -> Security : Network Security
A3: For easier request raising, template details for publishing will appear here sequentially. Blue-headed details auto-appear; green ones require completion in the MS Mindtickle Publishing list.
A5: Title | B5: Underscored Titles | C5: Title with underscores | D5: Clean Titles
A6: Lane MMF Transceiver Demo | C6: =IF(ISBLANK($A6),"",CLEAN(TRIM(SUBSTITUTE($A6," ","_")))) -> Lane_MMF_Transceiver_Demo | D6: =IF(ISBLANK($B6),"",TRIM(CLEAN(SUBSTITUTE($B6,"_"," "))))
C7: =IF(ISBLANK($A7),"",CLEAN(TRIM(SUBSTITUTE($A7," ","_")))) | D7: =IF(ISBLANK($B7),"",TRIM(CLEAN(SUBSTITUTE($B7,"_"," "))))
C8: =IF(ISBLANK($A8),"",CLEAN(TRIM(SUBSTITUTE($A8," ","_")))) | D8: =IF(ISBLANK($B8),"",TRIM(CLEAN(SUBSTITUTE($B8,"_"," "))))
C9: =IF(ISBLANK($A9),"",CLEAN(TRIM(SUBSTITUTE($A9," ","_")))) | D9: =IF(ISBLANK($B9),"",TRIM(CLEAN(SUBSTITUTE($B9,"_"," "))))
C10: =IF(ISBLANK($A10),"",CLEAN(TRIM(SUBSTITUTE($A10," ","_")))) | D10: =IF(ISBLANK($B10),"",TRIM(CLEAN(SUBSTITUTE($B10,"_"," "))))
C11: =IF(ISBLANK($A11),"",CLEAN(TRIM(SUBSTITUTE($A11," ","_")))) | D11: =IF(ISBLANK($B11),"",TRIM(CLEAN(SUBSTITUTE($B11,"_"," "))))
C12: =IF(ISBLANK($A12),"",CLEAN(TRIM(SUBSTITUTE($A12," ","_")))) | D12: =IF(ISBLANK($B12),"",TRIM(CLEAN(SUBSTITUTE($B12,"_"," "))))
C13: =IF(ISBLANK($A13),"",CLEAN(TRIM(SUBSTITUTE($A13," ","_")))) | D13: =IF(ISBLANK($B13),"",TRIM(CLEAN(SUBSTITUTE($B13,"_"," "))))
C14: =IF(ISBLANK($A14),"",CLEAN(TRIM(SUBSTITUTE($A14," ","_")))) | D14: =IF(ISBLANK($B14),"",TRIM(CLEAN(SUBSTITUTE($B14,"_"," "))))
C15: =IF(ISBLANK($A15),"",CLEAN(TRIM(SUBSTITUTE($A15," ","_")))) | D15: =IF(ISBLANK($B15),"",TRIM(CLEAN(SUBSTITUTE($B15,"_"," "))))
C16: =IF(ISBLANK($A16),"",CLEAN(TRIM(SUBSTITUTE($A16," ","_")))) | D16: =IF(ISBLANK($B16),"",TRIM(CLEAN(SUBSTITUTE($B16,"_"," "))))
C17: =IF(ISBLANK($A17),"",CLEAN(TRIM(SUBSTITUTE($A17," ","_")))) | D17: =IF(ISBLANK($B17),"",TRIM(CLEAN(SUBSTITUTE($B17,"_"," "))))
C18: =IF(ISBLANK($A18),"",CLEAN(TRIM(SUBSTITUTE($A18," ","_")))) | D18: =IF(ISBLANK($B18),"",TRIM(CLEAN(SUBSTITUTE($B18,"_"," "))))
... C104: =IF(ISBLANK($A104),"",CLEAN(TRIM(SUBSTITUTE($A104," ","_")))) | D104: =IF(ISBLANK($B104),"",TRIM(CLEAN(SUBSTITUTE($B104,"_"," "))))

Sheet Tiles
A1: Stage | B1: Tiles | C1: P Stage | D1: Tiles
A2: Stage1 | C2: PartnerStage1
A3: Stage2 | C3: PartnerStage2
A4: Stage3 | C4: PartnerStage3
A5: OG | C5: PartnerOG
A6: Track | C6: PartnerTrack
